# 흐름 제어

## 흐름 제어

### 흐름 제어 관련 요약

흐름 제어문

- return: 함수에서 결괏값을 반환하거나 지정된 라벨로 이동
- break: for 나 while 의 조건식에 상관없이 반복문을 끝냄
- continue: for 나 while 의 반복문의 본문을 모두 수행하지 않고 다시 조건으로 넘어감

예외 처리문

- try {...} catch {...}: try 블록을 수행하는 도중 예외가 발생하면 catch 블록 실행
- try {...} catch {...} finally {...}: 예외가 발생해도 finally 블록은 항상 실행

## return 의 사용

### return 으로 값 반환하기

```kotlin
fun add(a: Int, b: Int): Int {
    return a + b
    println("이 코드는 실행되지 않습니다.")
}
```

### return 으로 Unit 반환하기

```kotlin
// 1. Unit 을 명시적으로 반환
fun hello(name: String): Unit {
    println(name)
    return Unit
}

// 2. Unit 이름을 생략한 반환
fun hello(name: String): Unit {
    println(name)
    return
}

// 3. return 문 자체를 생략
fun hello(name: String) {
    println(name)
}
```

### 람다식에서 return 사용하기

```kotlin
fun main() {
    retFunc()
}

inline fun inlinelambda(a: Int, b: Int, out: (Int, Int) -> Unit){
    out(a,b)
}

fun retFunc() {
    println("start of retFunc")
    inlinelambda(1, 3) { a, b ->
        val result = a + b
        if(result > 10) return
        println("result: $result")
    }
    println("end of retFunc")
}
```

위 함수에서 result 값이 10보다 크면 return 되므로 end of retFunc 문구는 출력 되지 않느다.

### 람다식에서 라벨 사용

```kotlin
fun retFunc() {
    println("start of retFunc")
    inlinelambda(13, 3) lit@{ a, b ->
        val result = a + b
        if(result > 10) return@lit // 라벨을 사용한 블록의 끝부분으로 반환
        println("result: $result")
    }
    println("end of retFunc")
}
```

위위 함수에서 사용했던 코드에 lit 이라는 라벨을 추가 하였다.
result 값이 10보다 크면 lit 라벨로 return 된다. 
이때 lit 라벨을 사용한 블록의 끝부분으로 반환 되므로 end of retFunc 문구가 출력된다.

### 암묵적 라벨

```kotlin
fun retFunc() {
    println("start of retFunc")
    inlinelambda(13, 3) { a, b ->
        val result = a + b
        if(result > 10) return@inlinelambda
        println("result: $result")
    }
    println("end of retFunc")
}
```

위위 함수와 같은 결과가 나온다.
lit 라벨을 따로 붙이지 않아도 함수이름으로써 라벨과 같은 기능을 할 수 있다.

### 람다식과 익명 함수 사용

- 람다식 방법

```kotlin
val getMessage = lambda@ { num: Int ->
    if(num !in 1..100){
        return@lambda "Error"
    }
    "Success"
}
```

- 익명 함수 방법

```kotlin
val getMessage = fun(num: Int): String {
    if(num !in 1..100){
        return "Error"
    }
    return "Success"
}
```

## break 와 continue
### break 와 continue 의 사용

- for 나 while, do...while 문의 루프를 빠져 나옴

```kotlin
for (반복 조건) {
    // 본문
    if(중단 조건) {
        break
    }
    // 본문
}
```

중단 조건을 만족하면 반복문을 빠져나온다.

```kotlin
for (반복 조건) {
    // 본문
    if(중단 조건) {
        continue
    }
    // 본문
}
```

중단 조건을 만족하면 나머지 본문을 실행하지 않고 반복 조건으로 다시 넘어온다.

### break 와 라벨 함께 사용하기

- 라벨 없는 break 와 라벨을 사용한 break

```kotlin
fun labelBreak() {
    println("labelBreak")
    for(i in 1..5) {
        for (j in 1..5){
            if (j==3) break
            println("i: $i, j: $j")
        }
        println("after for j")
    }
    println("after for i")
}
```

```kotlin
fun labelBreak() {
    println("labelBreak")
    first@ for(i in 1..5) {
        second@ for (j in 1..5){
            if (j==3) break@first
            println("i: $i, j: $j")
        }
        println("after for j")
    }
    println("after for i")
}
```

첫 번째 코드는 break 시점에서 for 문 한개만 빠져나오게 된다.

두 번째 코드는 first 라벨을 가지고 있는 최상위 for 문을 빠져나오게 된다.

## 예외 처리
### 예외 (exception)

실행 도중의 잠재적인 오류까지 검사할 수 없기 때문에 정상적으로 실행이 되다가
비정상적으로 프로그램이 종료되는 경우

- 운영체제의 문제 (잘못된 시스템 호출의 문제)
- 입력값의 문제 (존재하지 않는 파일 혹은, 숫자 입력란에 문자 입력 등)
- 받아들일 수 없는 연산 (0으로 나누기 등)
- 메모리의 할당 실패 및 부족
- 컴퓨터 기계 자체의 문제 (전원 문제, 망가진 기억 장치 등)

### 예외를 대비하기 위한 구문

```kotlin
try{
    에외 발생 가능성 있는 문장
} catch (e: 예외처리 클래스 명){
    예외를 처리하기 위한 문장
} finally {
    반드시 실행되어야 하는 문장
}
```

finally 블록은 생략할 수 있다.

- ex 
```kotlin
fun main() {
    val a = 6
    val b = 0
    val c: Int

    try {
        c = a / b
        // 실행 되지 않음
        println("After")
    } catch (e: Exception) {
        println("Exception")
    } finally {
        println("finally")
    }
}

// 결과
// Exception
// Exception
```

### 특정 예외 처리

- 산술 연산에 대한 예외를 따로 특정해서 잡을 때

```kotlin
...
} catch (e: ArithmeticException) {
    println("Exception is handled. ${e.message}")
}

// Exception is handled. / by zero
```

- 스택의 추적

```kotlin
...
} catch (e: Exception) {
    e.printStackTrace()
}

// java.lang.ArithmeticException: / by zero
// at chapter5.section2.TryCatchKt.main(TryCatch.kt:9)
// at chapter5.section2.TryCatchKt.main(TryCatch.kt)
```

### 특정 조건에 따른 예외 발생

```kotlin
throw Exception(message: String)
```

